---
title: C# try catch块内为空程序不会崩溃
mathjax: false
date: 2020-11-23 10:22:00
tags: C#
categories: 编程爱好
---

catch块内为空程序不会崩溃, 只是代表它没有进行任何的处理而已。

<!--more-->
![](http://image.huvjie.com/201123N03_img01.jpg)

```CSharp
using System;
using System.Windows.Forms;

namespace ConsoleApp2
{
    public partial class Form1 : Form
    {
        public Form1()
        {
            InitializeComponent();
        }

        private void button1_Click(object sender, EventArgs e)
        {
            try
            {
                int a = 0;
                int b = 1;

                int c = b / a;
            }
			catch 
			{			
			}
           
        }
    }
}

```

上面这样程序不会蹦掉，只是没有处理异常而已。

很多时候，我们将错误信息`Show`出来。如下：

```CSharp
catch(Exception ex)
{
    MessageBox.Show(ex.Message);
}
```

当然，也可以进行其他的处理。